Workbook
Name AGAMA: [1]Master!$M$4:$M$10
Name DEPARTMENT: [1]Master!$E$4:$E$20
Name Division: [1]Master!$F$4:$F$8
Name GOLONGAN: [1]Master!$G$4:$G$51
Name GOLONGAN_DARAH: [2]Master!$L$4:$L$8
Name JABATAN_STRUKTURAL: #REF!
Name JABATAN_STRUKTURAL: #REF!
Name JABATAN_STRUKTURAL: #REF!
Name JENIS_KELAMIN: [1]Master!$K$4:$K$6
Name JOB_NAME: [2]Master!$B$4:$B$271
Name Pangkat: [2]Master!$D$4:$D$17
Name Pangkat: [2]Master!$D$4:$D$17
Name Pangkat: [2]Master!$D$4:$D$17
Name PENDIDIKAN: [2]Master!$J$4:$J$21
Name POH: [1]Master!$I$4:$I$10
Name STATUS: [1]Master!$H$4:$H$7
Name STATUS_TANGGUNGAN: [2]Master!$N$4:$N$12

Sheet 2018
A1: DAFTAR NAMA TENAGA KERJA
A3: =+NOW() -> 44202.499
A5: No. | B5: N I K * | C5: NAMA LENGKAP | D5: JABATAN * | E5: STATUS KARYAWAN | F5: TANGGAL MULAI KERJA | G5: MASA KERJA | K5: JENIS KELAMIN | L5: A G A M A | M5: TEMPAT LAHIR | N5: Tanggal Lahir | O5: Umur | Q5: PENDIDIKAN TERAKHIR | S5: GOLONGAN DARAH | T5: STATUS PERKAWINAN | U5: ISTERI/SUAMI | W5: ANAK I | Z5: ANAK II | AC5: ANAK III | AF5: KTP * | AH5: ALAMAT TINGGAL | AI5: NO. BPJS KETENAGAKERJAAN | AJ5: NO. BPJS KESEHATAN | AK5: NPWP | AL5: NO. HP | AM5: ACCOUNT BANK * | AQ5: EMAIL
G6: =+NOW() -> 44202.499 | I6: MULAI | J6: AKHIR | Q6: Pendidikan | R6: Jurusan | U6: Nama | V6: Tgl Lahir | W6: Nama | X6: Tgl Lahir | Y6: Umur | Z6: Nama | AA6: Tgl Lahir | AB6: Umur | AC6: Nama | AD6: Tgl Lahir | AE6: Pendidikan | AF6: NOMOR KTP | AG6: ALAMAT KTP | AM6: Atas Nama (sesuai dibuku rekening) | AN6: NOMOR REKENING | AO6: BANK | AP6: CABANG
G7: Tahun | H7: Bulan | N7: =+NOW() -> 44202.499 | O7: Tahun | P7: Bulan
A8: MANAGEMENT
C9: SHANDY PURNAMASARI | D9: KOMISARIS | K9: P | L9: ISLAM | M9: SURABAYA | N9: 33521 | O9: =DATEDIF(N9,$A$3,"Y") -> 29 | P9: =DATEDIF(N9,$A$3,"YM") -> 2 | T9: K/1 | U9: GILANG WIDYA PRAMANA | V9: 32632 | W9: FELICIA LASHA ZAFEERA | X9: 41559 | Y9: =DATEDIF(X9,$A$3,"Y") -> 7 | AH9: GREENWOOD GOLF INDAH NO. 5 - MALANG
C10: GILANG WIDYA PRAMANA | D10: DIREKTUR | K10: L | L10: ISLAM | M10: PROBOLINGGO | N10: 32632 | O10: =DATEDIF(N10,$A$3,"Y") -> 31 | P10: =DATEDIF(N10,$A$3,"YM") -> 8 | T10: K/1 | U10: SHANDY PURNAMASARI | V10: 33521 | W10: FELICIA LASHA ZAFEERA | X10: 41559 | Y10: =DATEDIF(X10,$A$3,"Y") -> 7 | AF10: 3574040405890001 | AG10: JL. KH AHMAD DAHLAN 123 RT.01/RW.01 PROBOLINGGO | AH10: GREENWOOD GOLF INDAH NO. 5 - MALANG | AK10: 35.447.918.0.625.000 | AL10: 081233732340
A11: BACK OFFICE
A12: 1 | B12: 9918040001 | C12: CITRA DWI MURDIYANTI | D12: MANAGER PRODUCT | E12: KONTRAK | F12: 43202 | G12: =DATEDIF(F12,$A$3,"Y") -> 2 | H12: =DATEDIF(F12,$A$3,"YM") -> 8 | K12: P | L12: ISLAM | M12: MALANG | N12: 33622 | O12: =DATEDIF(N12,$A$3,"Y") -> 28 | P12: =DATEDIF(N12,$A$3,"YM") -> 11 | Q12: SMK | R12: APK | S12: B | T12: K/1 | U12: RIFA'I SUNETH | V12: 32043 | W12: MUHAMMAD AL-AFZAN SUNETH | X12: 40734 | Y12: =DATEDIF(X12,$A$3,"Y") -> 9 | AF12: 3573015901920008 | AG12: PURI CEMPAKA PUTIH 3 BG 11 RT.05 RW.06 - MALANG | AH12: JL. MASJID NO. 22 KLAGEN TAJINAN - MALANG | AK12: - | AL12: 081334178380 | AM12: CITRA DWI MURDIYANTI | AN12: 1440016469386 | AO12: MANDIRI | AP12: MALANG - KCP SUPRAPTO | AQ12: citradwimurdiyanti19@gmail.com
A13: =A12+1 -> 2 | B13: 9918040002 | C13: CHANDRA MAHARDHIKA | D13: MANAGER OPERATION | E13: KONTRAK | F13: 43202 | G13: =DATEDIF(F13,$A$3,"Y") -> 2 | H13: =DATEDIF(F13,$A$3,"YM") -> 8 | K13: L | L13: ISLAM | M13: MALANG | N13: 32362 | O13: =DATEDIF(N13,$A$3,"Y") -> 32 | P13: =DATEDIF(N13,$A$3,"YM") -> 4 | Q13: S-2 | R13: MANAJ. SUMBER DAYA MANUSIA | S13: O | T13: K/1 | U13: FEBRIANA PUTRI ASIH VALENTINE | V13: 32188 | W13: ALARIC GHIBRAN MAHARDHIKA | X13: 42531 | Y13: =DATEDIF(X13,$A$3,"Y") -> 4 | AF13: 3573040708880003 | AG13: JL. RANAKAH Q-9 TIDAR - MALANG | AH13: JL. SIMPANG LOWOKDORO NO. 2 KAV. 1 - MALANG | AK13: 97.290.407.2.623.000 | AL13: 081233993341 | AM13: CHANDRA MAHARDHIKA | AN13: 1440017394153 | AO13: MANDIRI | AP13: MALANG - KCP SUPRAPTO | AQ13: mahardhika.chandra7888@gmail.com
A14: =A13+1 -> 3 | B14: 9918040003 | C14: KUMARA FOREST HIMAWAN | D14: DESIGN GRAPHIC | E14: KONTRAK | F14: 43202 | G14: =DATEDIF(F14,$A$3,"Y") -> 2 | H14: =DATEDIF(F14,$A$3,"YM") -> 8 | K14: L | L14: ISLAM | M14: MALANG | N14: 33885 | O14: =DATEDIF(N14,$A$3,"Y") -> 28 | P14: =DATEDIF(N14,$A$3,"YM") -> 2 | Q14: S-1 | R14: TI - DG | S14: O | T14: TK/0 | AF14: 3573040810920007 | AG14: JL. S. SUPRIADI A IX RT.07 RW.04 NO.26 - MALANG | AH14: JL. S. SUPRIADI A IX RT.07 RW.04 NO.26 - MALANG | AK14: 75.555.660.2.623.000 | AL14: 089680813467 | AM14: KUMARA FOREST H. | AN14: 1440017286805 | AO14: MANDIRI | AP14: MALANG - KCP SUPRAPTO | AQ14: kumarabunk@gmail.com
A15: =A14+1 -> 4 | B15: 9918080037 | C15: RIDA' MILLATI | D15: DESIGN GRAPHIC | E15: KONTRAK | F15: 43340 | G15: =DATEDIF(F15,$A$3,"Y") -> 2 | H15: =DATEDIF(F15,$A$3,"YM") -> 4 | K15: P | L15: ISLAM | M15: MALANG | N15: 34553 | O15: =DATEDIF(N15,$A$3,"Y") -> 26 | P15: =DATEDIF(N15,$A$3,"YM") -> 4 | Q15: S-1 | R15: DESAIN PRODUCT | S15: - | T15: TK/1 | W15: MIKAYLA ALESHA VALERIE | X15: 42598 | Y15: =DATEDIF(X15,$A$3,"Y") -> 4 | AF15: 3573044708940000 | AG15: JL. SIMPANG LOWOKDORO I no. 5 RT.10/RW.04 KEC. SUKUN - MALANG | AH15: JL. SIMPANG LOWOKDORO I no. 5 RT.10/RW.04 KEC. SUKUN - MALANG | AL15: 085257396000 | AM15: RIDA' MILLATI | AN15: 144001771808 | AO15: MANDIRI | AP15: MALANG - KCP SUPRAPTO | AQ15: rida.millati29@gmail.com
A16: =A15+1 -> 5 | B16: 9918110040 | C16: ANNISYA FERONICA | D16: DESIGN GRAPHIC | E16: KONTRAK | F16: 43407 | G16: =DATEDIF(F16,$A$3,"Y") -> 2 | H16: =DATEDIF(F16,$A$3,"YM") -> 2 | K16: P | L16: ISLAM | M16: BANYUWANGI | N16: 34813 | O16: =DATEDIF(N16,$A$3,"Y") -> 25 | P16: =DATEDIF(N16,$A$3,"YM") -> 8 | Q16: S-1 | R16: DESAIN PRODUCT | S16: - | T16: K/0 | AF16: 3510166404950004 | AG16: PERUM MENDUT REGENCY J/30, MOJOAGUNG - GIRI | AH16: JL. TELUK ETNA X KAV.145 NO.2 ARJOSARI - MALANG | AL16: 081333455035 | AM16: ANNISYA FERRONICA | AN16: 1440017967297 | AO16: MANDIRI | AP16: MALANG - KCP SUPRAPTO | AQ16: annisya.ferronica@gmail.com
A17: =A16+1 -> 6 | B17: 9918040005 | C17: OKY ARI AFANDI | D17: ADMIN OFFICE | E17: KONTRAK | F17: 43202 | G17: =DATEDIF(F17,$A$3,"Y") -> 2 | H17: =DATEDIF(F17,$A$3,"YM") -> 8 | K17: L | L17: ISLAM | M17: MALANG | N17: 33519 | O17: =DATEDIF(N17,$A$3,"Y") -> 29 | P17: =DATEDIF(N17,$A$3,"YM") -> 2 | Q17: S-1 | R17: MANAJEMEN | S17: - | T17: TK/0 | AF17: 3573040810910003 | AG17: JL. CANDI 5B/569 KEL. KARANGBESUKI- MALANG | AH17: JL. CANDI 5B/569 KEL. KARANGBESUKI- MALANG | AK17: - | AL17: 082236179998 | AM17: OKY ARI AFANDI | AN17: 1440016471978 | AO17: MANDIRI | AP17: MALANG - KCP SUPRAPTO | AQ17: ocky08traffict@gmail.com
A18: =A17+1 -> 7 | B18: 9918040006 | C18: VIOLA DWI PERMATASARI | D18: MARKETING | E18: KONTRAK | F18: 43202 | G18: =DATEDIF(F18,$A$3,"Y") -> 2 | H18: =DATEDIF(F18,$A$3,"YM") -> 8 | K18: P | L18: ISLAM | M18: MALANG | N18: 34969 | O18: =DATEDIF(N18,$A$3,"Y") -> 25 | P18: =DATEDIF(N18,$A$3,"YM") -> 3 | Q18: SMK | R18: MULTIMEDIA | S18: O | T18: TK/0 | AF18: 3579016709950002 | AG18: JL. LESTI UTARA NO. 91B RT.07/RW.03 - BATU | AH18: JL. LESTI UTARA NO. 91B RT.07/RW.03 - BATU | AK18: - | AL18: 082257886906 | AM18: VIOLA DWI PERMATASARI | AN18: 1440016867597 | AO18: MANDIRI | AP18: MALANG - KCP SUPRAPTO | AQ18: violapermatasari09@gmail.com
A19: =A18+1 -> 8 | B19: 9918050033 | C19: SARIFA AINI | D19: MARKETING | E19: KONTRAK | F19: 43222 | G19: =DATEDIF(F19,$A$3,"Y") -> 2 | H19: =DATEDIF(F19,$A$3,"YM") -> 8 | K19: P | L19: ISLAM | M19: MALANG | N19: 33553 | O19: =DATEDIF(N19,$A$3,"Y") -> 29 | P19: =DATEDIF(N19,$A$3,"YM") -> 1 | Q19: S1 | R19: ADMINISTRASI BISNIS | S19: B | T19: K/1 | U19: WICAKSONO HARYO | V19: 33482 | W19: KAUTSARYO GHIFARYAN AL ABIDZAR | X19: 42846 | Y19: =DATEDIF(X19,$A$3,"Y") -> 3 | AF19: 3573015111910002 | AG19: JL. DANAU JONGE H7 D-30 RT.04/RW.15 - MALANG | AH19: JL. DANAU JONGE H7 D-30 RT.04/RW.15 - MALANG | AK19: - | AL19: 081233625018 | AO19: MANDIRI | AP19: MALANG - KCP SUPRAPTO | AQ19: -
A20: =A19+1 -> 9 | B20: 9918090038 | C20: ANIKE WULANDARI | D20: ADMIN / MARKETING | E20: KONTRAK | F20: 43362 | G20: =DATEDIF(F20,$A$3,"Y") -> 2 | H20: =DATEDIF(F20,$A$3,"YM") -> 3 | K20: P | L20: ISLAM | M20: MALANG | N20: 34925 | O20: =DATEDIF(N20,$A$3,"Y") -> 25 | P20: =DATEDIF(N20,$A$3,"YM") -> 4 | Q20: S1 | R20: KESEHATAN MASYARAKAT | T20: TK/0 | AF20: 3507185408950003 | AG20: SINDUREJO RT.4/RW.3 BANJAREJO PAKIS - KAB. MALANG | AH20: SINDUREJO RT.4/RW.3 BANJAREJO PAKIS - KAB. MALANG | AK20: - | AL20: 085646660730 | AO20: MANDIRI | AQ20: anikewulandarii@gmail.com
A21: =A20+1 -> 10 | B21: 9918040031 | C21: SHEILA OLGATA WIDYASARI | D21: ADMIN / REGISTRASI | E21: KONTRAK | F21: 43216 | G21: =DATEDIF(F21,$A$3,"Y") -> 2 | H21: =DATEDIF(F21,$A$3,"YM") -> 8 | K21: L | L21: ISLAM | M21: MALANG | N21: 34617 | O21: =DATEDIF(N21,$A$3,"Y") -> 26 | P21: =DATEDIF(N21,$A$3,"YM") -> 2 | Q21: D-IV | R21: AKUNTANSI MANAJEMEN | S21: O | T21: TK/0 | AF21: 3507185010940001 | AG21: JL. GAJAHMADA RT.05/RW.02 BANJAREJO - PAKIS | AH21: JL. GAJAHMADA RT.05/RW.02 BANJAREJO - PAKIS | AK21: - | AL21: 085785233266 / 081336569356 | AO21: MANDIRI | AP21: MALANG - KCP SUPRAPTO
A22: =A21+1 -> 11 | B22: 9918040010 | C22: SLAMET HADI | D22: SECURITY | E22: KONTRAK | F22: 43202 | G22: =DATEDIF(F22,$A$3,"Y") -> 2 | H22: =DATEDIF(F22,$A$3,"YM") -> 8 | K22: L | L22: ISLAM | M22: MALANG | N22: 28657 | O22: =DATEDIF(N22,$A$3,"Y") -> 42 | P22: =DATEDIF(N22,$A$3,"YM") -> 6 | Q22: SD | R22: - | S22: - | T22: K/2 | U22: DIAH SAFITRI | W22: MAULIANA | Z22: MUHAMMAD FAJAR | AF22: 3573031606780004 | AG22: JL. KH MALIK DALAM RT.03/RW.04 - MALANG | AH22: JL. KH MALIK DALAM RT.03/RW.04 - MALANG | AK22: - | AL22: 082233385522 | AM22: SLAMET HADI | AN22: 1440017394179 | AO22: MANDIRI | AP22: MALANG - KCP SUPRAPTO | AQ22: hh987319@gmail.com
A23: =A22+1 -> 12 | B23: 9918070035 | C23: YULAIKA | D23: OFFICE GIRL / PANTRY | E23: KONTRAK | F23: 43299 | G23: =DATEDIF(F23,$A$3,"Y") -> 2 | H23: =DATEDIF(F23,$A$3,"YM") -> 5 | K23: P | L23: ISLAM | M23: MALANG | N23: 25432 | O23: =DATEDIF(N23,$A$3,"Y") -> 51 | P23: =DATEDIF(N23,$A$3,"YM") -> 4 | Q23: SD | R23: - | S23: - | AF23: 3507165708690002 | AG23: JL. NAKULA 29 RT.03/RW.014 - TUMPANG | AK23: - | AL23: 082143604353
A24: PACKING
A25: =A23+1 -> 13 | B25: 9918040011 | C25: INDRI WULANDARI | D25: STAFF PACKING | E25: KONTRAK | F25: 43202 | G25: =DATEDIF(F25,$A$3,"Y") -> 2 | H25: =DATEDIF(F25,$A$3,"YM") -> 8 | K25: P | L25: ISLAM | M25: MALANG | N25: 35286 | O25: =DATEDIF(N25,$A$3,"Y") -> 24 | P25: =DATEDIF(N25,$A$3,"YM") -> 4 | Q25: SMP | R25: - | S25: - | T25: K/1 | U25: SUHARTANTO | V25: 34153 | W25: FRISKA HARTANTI APRILIA | X25: 41374 | Y25: =DATEDIF(X25,$A$3,"Y") -> 7 | AF25: 3573034908960004 | AG25: JL. KI AGENG GRIBIG RT.02/RW.03 MALANG | AH25: JL. KI AGENG GRIBIG RT.02/RW.03 MALANG | AK25: - | AL25: 082140547865 | AM25: INDRI WULANDARI | AN25: 1440016469303 | AO25: MANDIRI | AP25: MALANG - KCP SUPRAPTO | AQ25: -
A26: =A25+1 -> 14 | B26: 9918040012 | C26: AULIA PRATAMA | D26: STAFF PACKING | E26: KONTRAK | F26: 43202 | G26: =DATEDIF(F26,$A$3,"Y") -> 2 | H26: =DATEDIF(F26,$A$3,"YM") -> 8 | K26: P | L26: ISLAM | M26: MOJOKERTO | N26: 35278 | O26: =DATEDIF(N26,$A$3,"Y") -> 24 | P26: =DATEDIF(N26,$A$3,"YM") -> 5 | Q26: SMK | R26: TATA BOGA | S26: O | T26: TK/0 | AF26: 3507234108960001 | AG26: PERUM GRIYA PERMATA ALAM BLOK LC-10 NGIJO - KAB. MALANG | AH26: JL. KUNTA BASWARA 8 NO. 5 | AK26: - | AL26: 081944946485 | AM26: AULIA PRATAMA | AN26: 1440016796960 | AO26: MANDIRI | AP26: MALANG - KCP SUPRAPTO | AQ26: -
A27: =A26+1 -> 15 | B27: 9918040013 | C27: DWI RAHMA TIWI | D27: PACKING HEAD | E27: KONTRAK | F27: 43202 | G27: =DATEDIF(F27,$A$3,"Y") -> 2 | H27: =DATEDIF(F27,$A$3,"YM") -> 8 | K27: P | L27: ISLAM | M27: MALANG | N27: 34738 | O27: =DATEDIF(N27,$A$3,"Y") -> 25 | P27: =DATEDIF(N27,$A$3,"YM") -> 10 | Q27: SMA | R27: IPA | S27: - | T27: TK/0 | AF27: 3507154802950001 | AG27: DSN KLAGEN RT.05/RW.03 TAJINAN | AH27: JL. MASJID RT.05 RW.03 KLAGEN, TAJINAN - MALANG | AK27: - | AL27: 085248706986 | AM27: DWI RAHMA TIWI | AN27: 1440016469246 | AO27: MANDIRI | AP27: MALANG - KCP SUPRAPTO | AQ27: dwirahma.dr95.dr@gmail.com
A28: =A27+1 -> 16 | B28: 9918040014 | C28: IMELDA SUNETH | D28: STAFF PACKING | E28: KONTRAK | F28: 43202 | G28: =DATEDIF(F28,$A$3,"Y") -> 2 | H28: =DATEDIF(F28,$A$3,"YM") -> 8 | K28: P | L28: ISLAM | M28: WAKAL | N28: 31591 | O28: =DATEDIF(N28,$A$3,"Y") -> 34 | P28: =DATEDIF(N28,$A$3,"YM") -> 6 | Q28: SMK | R28: AKUNTANSI | S28: - | T28: TK/0 | AF28: 8101156806860002 | AG28: WIK GANEMO - WAKAL KEC. LEIHITU | AH28: JL. MASJID RT.05 RW.03 KLAGEN, TAJINAN - MALANG | AK28: - | AL28: 081391122559 | AM28: IMELDA SUNETH | AN28: 1440016530658 | AO28: MANDIRI | AP28: MALANG - KCP SUPRAPTO | AQ28: -
A29: =A28+1 -> 17 | B29: 9918040015 | C29: IRANING RAHAYU | D29: STAFF PACKING | E29: KONTRAK | F29: 43202 | G29: =DATEDIF(F29,$A$3,"Y") -> 2 | H29: =DATEDIF(F29,$A$3,"YM") -> 8 | K29: P | L29: ISLAM | M29: MALANG | N29: 31895 | O29: =DATEDIF(N29,$A$3,"Y") -> 33 | P29: =DATEDIF(N29,$A$3,"YM") -> 8 | Q29: SMP | R29: - | S29: - | T29: K/1 | U29: MOCH. FAUJI | V29: 29878 | W29: NAILA FAUZIATUROHMA | X29: 39899 | Y29: =DATEDIF(X29,$A$3,"Y") -> 11 | AF29: 3507156503870001 | AG29: JL. RADEN SALEH DSN PABRIAN RT.15/RW.03 BULULAWANG | AH29: JL. RADEN SALEH DSN PABRIAN RT.15/RW.03 BULULAWANG | AK29: - | AL29: 085646326911 | AM29: IRANING RAHAYU | AN29: 1440016469444 | AO29: MANDIRI | AP29: MALANG - KCP SUPRAPTO | AQ29: -
A30: =A29+1 -> 18 | B30: 9918040016 | C30: KHOLID MASRUROH | D30: STAFF PACKING | E30: KONTRAK | F30: 43202 | G30: =DATEDIF(F30,$A$3,"Y") -> 2 | H30: =DATEDIF(F30,$A$3,"YM") -> 8 | K30: P | L30: ISLAM | M30: MALANG | N30: 35350 | O30: =DATEDIF(N30,$A$3,"Y") -> 24 | P30: =DATEDIF(N30,$A$3,"YM") -> 2 | Q30: SMK | R30: ADMINISTRASI | S30: - | T30: TK/0 | AF30: 3507155210960001 | AG30: DS. TAJINAN RT.05/RW.03 TAJINAN | AH30: DS. TAJINAN RT.05/RW.03 TAJINAN | AK30: - | AL30: 082249062212 | AM30: KHOLID MASRUROH | AN30: 1440017224251 | AO30: MANDIRI | AP30: MALANG - KCP SUPRAPTO | AQ30: -
A31: =A30+1 -> 19 | B31: 9918040017 | C31: KIKI ANIKA PUTRI | D31: STAFF PACKING | E31: KONTRAK | F31: 43202 | G31: =DATEDIF(F31,$A$3,"Y") -> 2 | H31: =DATEDIF(F31,$A$3,"YM") -> 8 | K31: P | L31: ISLAM | M31: MALANG | N31: 33625 | O31: =DATEDIF(N31,$A$3,"Y") -> 28 | P31: =DATEDIF(N31,$A$3,"YM") -> 11 | Q31: SMK | R31: TEKNIK KOMP. & JARINGAN | S31: - | T31: K/1 | U31: RILO PAMBUDI LAKSONO | V31: 31472 | W31: NAJWA AVRILLIA PUTRI | X31: 41736 | Y31: =DATEDIF(X31,$A$3,"Y") -> 6 | AF31: 3507156201920003 | AG31: JL. MASJID NO 29 RT.05/RW.03 TAJINAN | AH31: JL. MASJID NO 29 RT.05/RW.03 TAJINAN | AK31: - | AL31: 085288777220 | AM31: KIKI ANIKA PUTRI | AN31: 1440016469345 | AO31: MANDIRI | AP31: MALANG - KCP SUPRAPTO | AQ31: -
A32: =A31+1 -> 20 | B32: 9918040018 | C32: NUR HALIMAH | D32: STAFF PACKING | E32: KONTRAK | F32: 43202 | G32: =DATEDIF(F32,$A$3,"Y") -> 2 | H32: =DATEDIF(F32,$A$3,"YM") -> 8 | K32: P | L32: ISLAM | M32: MALANG | N32: 34105 | O32: =DATEDIF(N32,$A$3,"Y") -> 27 | P32: =DATEDIF(N32,$A$3,"YM") -> 7 | Q32: SD | R32: - | S32: B | T32: K/1 | U32: AHMAD JAENURI | V32: 31029 | W32: MOCH. NIZAM ZULFIKAR | X32: 40959 | Y32: =DATEDIF(X32,$A$3,"Y") -> 8 | AF32: 3573035605930008 | AG32: JL. KALIANYAR RT.04/RW.01 WONOKOYO | AH32: JL. KH. MALIK DALAM RT.03/RW.04, BURING | AK32: - | AL32: 085853508699 | AM32: NUR HALIMAH | AN32: 1440016469329 | AO32: MANDIRI | AP32: MALANG - KCP SUPRAPTO | AQ32: -
A33: =A32+1 -> 21 | B33: 9918040019 | C33: RISA WULANDARI | D33: STAFF PACKING | E33: KONTRAK | F33: 43202 | G33: =DATEDIF(F33,$A$3,"Y") -> 2 | H33: =DATEDIF(F33,$A$3,"YM") -> 8 | K33: P | L33: ISLAM | M33: MALANG | N33: 31305 | O33: =DATEDIF(N33,$A$3,"Y") -> 35 | P33: =DATEDIF(N33,$A$3,"YM") -> 3 | Q33: SMA | R33: IPA | S33: - | T33: TK/1 | W33: NABILA WIDYA SAFIRA | X33: 39614 | Y33: =DATEDIF(X33,$A$3,"Y") -> 12 | AF33: 3507155509850001 | AG33: JL. MASJID NO 29 RT.05/RW.03 TAJINAN | AH33: JL. MASJID NO 29 RT.05/RW.03 TAJINAN | AK33: - | AL33: 081334767844 | AM33: RISA WULANDARI | AN33: 1440016469238 | AO33: MANDIRI | AP33: MALANG - KCP SUPRAPTO | AQ33: -
A34: =A33+1 -> 22 | B34: 9918040020 | C34: MAULIANA | D34: STAFF PACKING | E34: KONTRAK | F34: 43202 | G34: =DATEDIF(F34,$A$3,"Y") -> 2 | H34: =DATEDIF(F34,$A$3,"YM") -> 8 | K34: P | L34: ISLAM | M34: MALANG | N34: 37047 | O34: =DATEDIF(N34,$A$3,"Y") -> 19 | P34: =DATEDIF(N34,$A$3,"YM") -> 7 | Q34: SD | R34: - | S34: O | T34: TK/0 | AF34: - | AH34: JL. KH. MALIK DALAM BURING | AK34: - | AL34: 089649999391 | AM34: MAULIANA | AN34: 1440016469436 | AO34: MANDIRI | AP34: MALANG - KCP SUPRAPTO | AQ34: -
A35: =A34+1 -> 23 | B35: 9918040021 | C35: AHMAD MIFTACHUL ULUM | D35: STAFF PACKING | E35: KONTRAK | F35: 43202 | G35: =DATEDIF(F35,$A$3,"Y") -> 2 | H35: =DATEDIF(F35,$A$3,"YM") -> 8 | K35: L | L35: ISLAM | M35: MALANG | N35: 35595 | O35: =DATEDIF(N35,$A$3,"Y") -> 23 | P35: =DATEDIF(N35,$A$3,"YM") -> 6 | Q35: SMK | R35: KIMIA INDUSTRI | S35: - | T35: TK/0 | AF35: 3507171406970001 | AG35: JL. BRAWIJAYA KEPUH RT.44/RW.11 SUKOPURO - JABUNG | AH35: JL. BRAWIJAYA KEPUH RT.44/RW.11 SUKOPURO - JABUNG | AK35: - | AL35: 085881092663 | AM35: AHMAD MIFTAHUL ULUM | AN35: 1440017358059 | AO35: MANDIRI | AP35: MALANG - KCP SUPRAPTO | AQ35: ahmadulum207@gmail.com
A36: =A35+1 -> 24 | B36: 9918040022 | C36: NOFITASARI | D36: STAFF PACKING | E36: KONTRAK | F36: 43202 | G36: =DATEDIF(F36,$A$3,"Y") -> 2 | H36: =DATEDIF(F36,$A$3,"YM") -> 8 | K36: P | L36: ISLAM | M36: MALANG | N36: 35068 | O36: =DATEDIF(N36,$A$3,"Y") -> 25 | P36: =DATEDIF(N36,$A$3,"YM") -> 0 | Q36: SMP | R36: - | S36: O | T36: TK/0 | AF36: 3507184401960005 | AG36: DSN COKRO RT.04/RW.02 SUKOANYAR PAKIS | AH36: DSN COKRO RT.04/RW.02 SUKOANYAR PAKIS | AK36: - | AL36: 085755763644 | AM36: NOFITA SARI | AN36: 1440017357333 | AO36: MANDIRI | AP36: MALANG - KCP SUPRAPTO
A37: =A36+1 -> 25 | B37: 9918040024 | C37: FATCHUL AMIN | D37: STAFF PACKING | E37: KONTRAK | F37: 43202 | G37: =DATEDIF(F37,$A$3,"Y") -> 2 | H37: =DATEDIF(F37,$A$3,"YM") -> 8 | K37: L | L37: ISLAM | M37: MALANG | N37: 35463 | O37: =DATEDIF(N37,$A$3,"Y") -> 23 | P37: =DATEDIF(N37,$A$3,"YM") -> 11 | Q37: MA | R37: IPA | S37: O | T37: TK/0 | AF37: 3507150202970001 | AG37: TAJINAN RT.05/RW.03 TAJINAN | AH37: TAJINAN RT.05/RW.03 TAJINAN | AK37: - | AL37: 085843710881 | AM37: FATCHUL AMIN | AN37: 1440017357275 | AO37: MANDIRI | AP37: MALANG - KCP SUPRAPTO | AQ37: -
A38: =A37+1 -> 26 | B38: 9918040025 | C38: RIASULIS TIANING | D38: STAFF PACKING | E38: KONTRAK | F38: 43202 | G38: =DATEDIF(F38,$A$3,"Y") -> 2 | H38: =DATEDIF(F38,$A$3,"YM") -> 8 | K38: P | L38: ISLAM | M38: MALANG | N38: 34056 | O38: =DATEDIF(N38,$A$3,"Y") -> 27 | P38: =DATEDIF(N38,$A$3,"YM") -> 9 | Q38: SMP | R38: - | S38: - | T38: K/0 | U38: AHMAD ARDIANTO | V38: 33005 | AF38: 3507185503930001 | AG38: DUSUN KARANGNONGKO RT.01/RW.01 DESA PUCANG SONGO - PAKIS | AH38: DUSUN KARANGNONGKO RT.01/RW.01 DESA PUCANG SONGO - PAKIS | AK38: - | AL38: 083848371870 | AM38: RIASULIS TIANING | AN38: 1440016530633 | AO38: MANDIRI | AP38: MALANG - KCP SUPRAPTO
A39: =A38+1 -> 27 | B39: 9918080036 | C39: USMAN AINUR RIZKY | D39: STAFF PACKING | E39: KONTRAK | F39: 43330 | G39: =DATEDIF(F39,$A$3,"Y") -> 2 | H39: =DATEDIF(F39,$A$3,"YM") -> 4 | K39: L | L39: ISLAM | M39: MALANG | N39: 36332 | O39: =DATEDIF(N39,$A$3,"Y") -> 21 | P39: =DATEDIF(N39,$A$3,"YM") -> 6 | Q39: SMA | R39: - | S39: - | T39: TK/0 | AO39: MANDIRI | AP39: MALANG - KCP SUPRAPTO
A40: =A39+1 -> 28 | B40: 9918100039 | C40: SLAMET ARISUSANTO | D40: STAFF PACKING | E40: KONTRAK | F40: 43398 | G40: =DATEDIF(F40,$A$3,"Y") -> 2 | H40: =DATEDIF(F40,$A$3,"YM") -> 2 | K40: L | L40: ISLAM | M40: MALANG | N40: 32168 | O40: =DATEDIF(N40,$A$3,"Y") -> 32 | P40: =DATEDIF(N40,$A$3,"YM") -> 11 | Q40: SMA | R40: - | S40: - | T40: K/1 | AO40: MANDIRI | AP40: MALANG - KCP SUPRAPTO
A41: =A40+1 -> 29 | B41: 9918120041 | C41: MUHAMMAD NUR SHODIQ | D41: STAFF PACKING | E41: KONTRAK | F41: 43435 | G41: =DATEDIF(F41,$A$3,"Y") -> 2 | H41: =DATEDIF(F41,$A$3,"YM") -> 1 | K41: L | L41: ISLAM | M41: BOJONEGORO | N41: 35297 | O41: =DATEDIF(N41,$A$3,"Y") -> 24 | P41: =DATEDIF(N41,$A$3,"YM") -> 4 | Q41: SMA | R41: - | S41: - | T41: TK/0 | AH41: JL. ARGOPURO KECAMATAN LAWANG RT.03/RW.08 - LAWANG | AK41: - | AL41: 085791990276 | AO41: MANDIRI | AP41: MALANG - KCP SUPRAPTO
A42: DRIVER
...

Sheet 2019
A1: DAFTAR NAMA TENAGA KERJA
A3: =+NOW() -> 44202.499
A5: No. | B5: N I K * | C5: NAMA LENGKAP | D5: JABATAN * | E5: STATUS KARYAWAN | F5: TANGGAL MULAI KERJA | G5: STATUS KEPEGAWAIAN | J5: MASA KERJA | N5: JENIS KELAMIN | O5: A G A M A | P5: TEMPAT LAHIR | Q5: Tanggal Lahir | R5: Umur | T5: PENDIDIKAN TERAKHIR | V5: GOLONGAN DARAH | W5: STATUS PERKAWINAN | X5: ISTERI/SUAMI | Z5: ANAK I | AC5: ANAK II | AF5: ANAK III | AI5: KTP * | AK5: ALAMAT TINGGAL | AL5: NO. BPJS KETENAGAKERJAAN | AM5: NO. BPJS KESEHATAN | AN5: NPWP | AO5: NO. HP | AP5: ACCOUNT BANK * | AT5: EMAIL
J6: =+NOW() -> 44202.499 | L6: MULAI | M6: AKHIR | T6: Pendidikan | U6: Jurusan | X6: Nama | Y6: Tgl Lahir | Z6: Nama | AA6: Tgl Lahir | AB6: Umur | AC6: Nama | AD6: Tgl Lahir | AE6: Umur | AF6: Nama | AG6: Tgl Lahir | AH6: Pendidikan | AI6: NOMOR KTP | AJ6: ALAMAT KTP | AP6: Atas Nama (sesuai dibuku rekening) | AQ6: NOMOR REKENING | AR6: BANK | AS6: CABANG
G7: KONTRAK 1 (1 THN) | H7: KONTRAK 2 (2 THN) | I7: TETAP | J7: Tahun | K7: Bulan | Q7: =+NOW() -> 44202.499 | R7: Tahun | S7: Bulan
A8: MANAGEMENT
C9: SHANDY PURNAMASARI | D9: KOMISARIS | N9: P | O9: ISLAM | P9: SURABAYA | Q9: 33521 | R9: =DATEDIF(Q9,$A$3,"Y") -> 29 | S9: =DATEDIF(Q9,$A$3,"YM") -> 2 | W9: K/1 | X9: GILANG WIDYA PRAMANA | Y9: 32632 | Z9: FELICIA LASHA ZAFEERA | AA9: 41559 | AB9: =DATEDIF(AA9,$A$3,"Y") -> 7 | AK9: GREENWOOD GOLF INDAH NO. 5 - MALANG
C10: GILANG WIDYA PRAMANA | D10: DIREKTUR | N10: L | O10: ISLAM | P10: PROBOLINGGO | Q10: 32632 | R10: =DATEDIF(Q10,$A$3,"Y") -> 31 | S10: =DATEDIF(Q10,$A$3,"YM") -> 8 | W10: K/1 | X10: SHANDY PURNAMASARI | Y10: 33521 | Z10: FELICIA LASHA ZAFEERA | AA10: 41559 | AB10: =DATEDIF(AA10,$A$3,"Y") -> 7 | AI10: 3574040405890001 | AJ10: JL. KH AHMAD DAHLAN 123 RT.01/RW.01 PROBOLINGGO | AK10: GREENWOOD GOLF INDAH NO. 5 - MALANG | AN10: 35.447.918.0.625.000 | AO10: 081233732340
A11: BACK OFFICE
A12: 1 | B12: 9918040002 | C12: CHANDRA MAHARDHIKA | D12: MANAGER PRODUCT | E12: KONTRAK | F12: 43202 | G12: 43202 | H12: 43567 | J12: =DATEDIF(F12,$A$3,"Y") -> 2 | K12: =DATEDIF(F12,$A$3,"YM") -> 8 | N12: L | O12: ISLAM | P12: MALANG | Q12: 32362 | R12: =DATEDIF(Q12,$A$3,"Y") -> 32 | S12: =DATEDIF(Q12,$A$3,"YM") -> 4 | T12: S-2 | U12: MANAJ. SUMBER DAYA MANUSIA | V12: O | W12: K/1 | X12: FEBRIANA PUTRI ASIH VALENTINE | Y12: 32188 | Z12: ALARIC GHIBRAN MAHARDHIKA | AA12: 42531 | AB12: =DATEDIF(AA12,$A$3,"Y") -> 4 | AC12: - | AD12: - | AE12: - | AI12: 3573040708880003 | AJ12: JL. RANAKAH Q-9 TIDAR - MALANG | AK12: JL. SIMPANG LOWOKDORO NO. 2 KAV. 1 - MALANG | AN12: 97.290.407.2.623.000 | AO12: 081233993341 | AP12: CHANDRA MAHARDHIKA | AQ12: 144-00-1739415-3 | AR12: MANDIRI | AS12: MALANG - KCP SUPRAPTO | AT12: mahardhika.chandra7888@gmail.com
A13: 2 | B13: 9919010001 | C13: AISAH RACHMAWATI | D13: ACCOUNTING | E13: KONTRAK | F13: 43467 | G13: 43467 | J13: =DATEDIF(F13,$A$3,"Y") -> 2 | K13: =DATEDIF(F13,$A$3,"YM") -> 0 | N13: P | O13: ISLAM | P13: MALANG | Q13: 34474 | R13: =DATEDIF(Q13,$A$3,"Y") -> 26 | S13: =DATEDIF(Q13,$A$3,"YM") -> 7 | T13: S-1 | U13: AKUNTANSI | V13: A | W13: TK/0 | X13: - | Y13: - | Z13: - | AA13: - | AB13: - | AC13: - | AD13: - | AE13: - | AI13: 3573026005940004 | AJ13: JL. TAPAK SIRING II/43E RT.05/RW.08 KEL. SAMAAN - MALANG | AK13: JL. TAPAK SIRING II/43E RT.05/RW.08 KEL. SAMAAN - MALANG | AN13: - | AO13: 081252696065 | AP13: AISAH RACHMAWATI | AQ13: 144-00-1811601-9 | AR13: MANDIRI | AS13: MALANG - KCP SUPRAPTO | AT13: aiss20rachman@gmail.com
A14: 3 | B14: 9919020011 | C14: VENNA ROSIA MARHETA | D14: MANAGER HRGA | E14: KONTRAK | F14: 43497 | G14: 43497 | J14: =DATEDIF(F14,$A$3,"Y") -> 1 | K14: =DATEDIF(F14,$A$3,"YM") -> 11 | N14: P | O14: ISLAM | P14: MALANG | Q14: 31666 | R14: =DATEDIF(Q14,$A$3,"Y") -> 34 | S14: =DATEDIF(Q14,$A$3,"YM") -> 3 | T14: S-2 | U14: MANAJ. SUMBER DAYA MANUSIA | V14: A | W14: K/1 | X14: MOH. HASIM AS'ARI | Y14: 30600 | Z14: GHAIDA AMETHYSA SHANUM | AA14: 41939 | AB14: =DATEDIF(AA14,$A$3,"Y") -> 6 | AC14: - | AD14: - | AE14: - | AI14: 3573045109860002 | AJ14: JL. RAYA GADANG XB NO 49 RT.04/RW.05 KEL. GADANG - MALANG | AK14: JL. RAYA GADANG XB NO 48 RT.04/RW.05 KEL. GADANG - MALANG | AN14: 08.735.462.7-623.000 | AO14: 0895627070220 | AP14: VENNA ROSIA MARHETA | AQ14: 144-00-1818033-8 | AR14: MANDIRI | AS14: MALANG - KCP SUPRAPTO | AT14: verota.pussie@gmail.com
A15: 4 | B15: 9919020012 | C15: DENI LUQMANA | D15: PURCHASING | E15: KONTRAK | F15: 43497 | G15: 43497 | J15: =DATEDIF(F15,$A$3,"Y") -> 1 | K15: =DATEDIF(F15,$A$3,"YM") -> 11 | N15: L | O15: ISLAM | P15: PROBOLINGGO | Q15: 33977 | R15: =DATEDIF(Q15,$A$3,"Y") -> 27 | S15: =DATEDIF(Q15,$A$3,"YM") -> 11 | T15: S-1 | U15: SOSIOLOGI | V15: B | W15: TK/0 | X15: - | Y15: - | Z15: - | AA15: - | AB15: - | AC15: - | AD15: - | AE15: - | AI15: 3574020801930001 | AJ15: PERUM SUMBER TAMAN INDAH BLOK D-14 PROBOLINGGO | AK15: PERUM PERMATA JINGGA BLOK SAWO 19 MALANG | AN15: 80.153.482.7-625.000 | AO15: 082234653862 | AP15: DENI LUQMANA | AQ15: 144-00-1818035-3 | AR15: MANDIRI | AS15: MALANG - KCP SUPRAPTO | AT15: deniluqmana1@gmail.com
A16: 5 | B16: 9918040003 | C16: KUMARA FOREST HIMAWAN | D16: DESAIN GRAFIS | E16: KONTRAK | F16: 43202 | G16: 43202 | H16: 43567 | J16: =DATEDIF(F16,$A$3,"Y") -> 2 | K16: =DATEDIF(F16,$A$3,"YM") -> 8 | N16: L | O16: ISLAM | P16: MALANG | Q16: 33885 | R16: =DATEDIF(Q16,$A$3,"Y") -> 28 | S16: =DATEDIF(Q16,$A$3,"YM") -> 2 | T16: S-1 | U16: TI - DG | V16: O | W16: TK/0 | X16: - | Y16: - | Z16: - | AA16: - | AB16: - | AC16: - | AD16: - | AE16: - | AI16: 3573040810920007 | AJ16: JL. S. SUPRIADI A IX RT.07 RW.04 NO.26 - MALANG | AK16: JL. S. SUPRIADI A IX RT.07 RW.04 NO.26 - MALANG | AN16: 75.555.660.2.623.000 | AO16: 089680813467 | AP16: KUMARA FOREST H. | AQ16: 144-00-1728680-5 | AR16: MANDIRI | AS16: MALANG - KCP SUPRAPTO | AT16: kumarabunk@gmail.com
A17: 6 | B17: 9918080037 | C17: RIDA' MILLATI | D17: GENERAL MANAGER | E17: KONTRAK | F17: 43340 | G17: 43340 | J17: =DATEDIF(F17,$A$3,"Y") -> 2 | K17: =DATEDIF(F17,$A$3,"YM") -> 4 | N17: P | O17: ISLAM | P17: MALANG | Q17: 34553 | R17: =DATEDIF(Q17,$A$3,"Y") -> 26 | S17: =DATEDIF(Q17,$A$3,"YM") -> 4 | T17: S-1 | U17: DESAIN PRODUCT | V17: - | W17: TK/1 | X17: - | Y17: - | Z17: MIKAYLA ALESHA VALERIE | AA17: 42598 | AB17: =DATEDIF(AA17,$A$3,"Y") -> 4 | AC17: - | AD17: - | AE17: - | AI17: 3573044708940000 | AJ17: JL. SIMPANG LOWOKDORO I no. 5 RT.10/RW.04 KEC. SUKUN - MALANG | AK17: JL. SIMPANG LOWOKDORO I no. 5 RT.10/RW.04 KEC. SUKUN - MALANG | AN17: - | AO17: 085257396000 | AP17: RIDA' MILLATI | AQ17: 144-00-1771808-8 | AR17: MANDIRI | AS17: MALANG - KCP SUPRAPTO | AT17: rida.millati29@gmail.com
A18: 7 | B18: 9919010006 | C18: ROY | D18: DESAIN GRAFIS | E18: KONTRAK | F18: 43469 | G18: 43469 | J18: =DATEDIF(F18,$A$3,"Y") -> 2 | K18: =DATEDIF(F18,$A$3,"YM") -> 0 | N18: L | O18: ISLAM | P18: MALANG | Q18: 33831 | R18: =DATEDIF(Q18,$A$3,"Y") -> 28 | S18: =DATEDIF(Q18,$A$3,"YM") -> 4 | T18: S-1 | U18: TI - DG | V18: - | W18: K/0 | X18: RIMA DHANI RAHMA SUWANDI | Y18: 35454 | Z18: - | AA18: - | AB18: - | AC18: - | AD18: - | AE18: - | AI18: 3507191508920002 | AJ18: JL. GARUDA RT.06/RW.02 DS. KARANGPANDAN - PAKISAJI | AK18: JL. GARUDA RT.06/RW.02 DS. KARANGPANDAN - PAKISAJI | AN18: - | AO18: 085736881552 | AP18: ROY | AQ18: 144-00-1811609-2 | AR18: MANDIRI | AS18: MALANG - KCP SUPRAPTO | AT18: secondsecret.2nd@gmail.
A19: 8 | B19: 9919020013 | C19: USHA FATNIA AUDRINISA | D19: DESAIN GRAFIS | E19: KONTRAK | F19: 43511 | G19: 43511 | J19: =DATEDIF(F19,$A$3,"Y") -> 1 | K19: =DATEDIF(F19,$A$3,"YM") -> 10 | N19: P | O19: ISLAM | P19: MALANG | Q19: 34934 | R19: =DATEDIF(Q19,$A$3,"Y") -> 25 | S19: =DATEDIF(Q19,$A$3,"YM") -> 4 | T19: S-1 | U19: INTERACTIVE AND VISUAL DESIGN | V19: B | W19: TK/0 | X19: - | Y19: - | Z19: - | AA19: - | AB19: - | AC19: - | AD19: - | AE19: - | AI19: 3573026308950002 | AJ19: JL RAUNG 4 005/005 ORO-ORO DOWO KLOJEN MALANG | AK19: JL RAUNG 4 005/005 ORO-ORO DOWO KLOJEN MALANG | AN19: - | AO19: 081332310462 | AP19: USHA FATNIA AUDRINISA | AQ19: 144-00-1819114-5 | AR19: MANDIRI | AS19: MALANG - KCP SUPRAPTO | AT19: usha.fatnia@gmail.com
A20: 9 | B20: 9919010003 | C20: ALONG ALFIAH | D20: ADMIN OFFICE | E20: KONTRAK | F20: 43467 | G20: 43467 | J20: =DATEDIF(F20,$A$3,"Y") -> 2 | K20: =DATEDIF(F20,$A$3,"YM") -> 0 | N20: P | O20: ISLAM | P20: PROBOLINGGO | Q20: 35726 | R20: =DATEDIF(Q20,$A$3,"Y") -> 23 | S20: =DATEDIF(Q20,$A$3,"YM") -> 2 | T20: D-I | U20: ADM. PERKANTORAN | V20: B+ | W20: TK/0 | X20: - | Y20: - | Z20: - | AA20: - | AB20: - | AC20: - | AD20: - | AE20: - | AI20: 3513056310970003 | AJ20: JL. IR SUTAMI DS. JORONGAN KEC. LECES - PROBOLINGGO | AK20: JL. IR SUTAMI DS. JORONGAN KEC. LECES - PROBOLINGGO | AN20: - | AO20: 085559612295 | AP20: ALONG ALFIAH | AQ20: 144-00-1692098-2 | AR20: MANDIRI | AS20: MALANG - KCP SUPRAPTO | AT20: along.alfiah@gmail.com
A21: 10 | B21: 9918040005 | C21: OKY ARI AFANDI | D21: ADMIN OFFICE | E21: KONTRAK | F21: 43202 | G21: 43202 | H21: 43567 | J21: =DATEDIF(F21,$A$3,"Y") -> 2 | K21: =DATEDIF(F21,$A$3,"YM") -> 8 | N21: L | O21: ISLAM | P21: MALANG | Q21: 33519 | R21: =DATEDIF(Q21,$A$3,"Y") -> 29 | S21: =DATEDIF(Q21,$A$3,"YM") -> 2 | T21: S-1 | U21: MANAJEMEN | V21: - | W21: TK/0 | X21: - | Y21: - | Z21: - | AA21: - | AB21: - | AC21: - | AD21: - | AE21: - | AI21: 3573040810910003 | AJ21: JL. CANDI 5B/569 KEL. KARANGBESUKI- MALANG | AK21: JL. CANDI 5B/569 KEL. KARANGBESUKI- MALANG | AN21: - | AO21: 082236179998 | AP21: OKY ARI AFANDI | AQ21: 144-00-1647197-8 | AR21: MANDIRI | AS21: MALANG - KCP SUPRAPTO | AT21: ocky08traffict@gmail.com
A22: 11 | B22: 9918040006 | C22: VIOLA DWI PERMATASARI | D22: MARKETING | E22: KONTRAK | F22: 43202 | G22: 43202 | H22: 43567 | J22: =DATEDIF(F22,$A$3,"Y") -> 2 | K22: =DATEDIF(F22,$A$3,"YM") -> 8 | N22: P | O22: ISLAM | P22: MALANG | Q22: 34969 | R22: =DATEDIF(Q22,$A$3,"Y") -> 25 | S22: =DATEDIF(Q22,$A$3,"YM") -> 3 | T22: SMK | U22: MULTIMEDIA | V22: O | W22: TK/0 | X22: - | Y22: - | Z22: - | AA22: - | AB22: - | AC22: - | AD22: - | AE22: - | AI22: 3579016709950002 | AJ22: JL. LESTI UTARA NO. 91B RT.07/RW.03 - BATU | AK22: JL. LESTI UTARA NO. 91B RT.07/RW.03 - BATU | AN22: - | AO22: 082257886906 | AP22: VIOLA DWI PERMATASARI | AQ22: 144-00-1686759-7 | AR22: MANDIRI | AS22: MALANG - KCP SUPRAPTO | AT22: violapermatasari09@gmail.com
A23: 12 | B23: 9918050033 | C23: SARIFA AINI | D23: MARKETING | E23: KONTRAK | F23: 43222 | G23: 43222 | H23: 43587 | J23: =DATEDIF(F23,$A$3,"Y") -> 2 | K23: =DATEDIF(F23,$A$3,"YM") -> 8 | N23: P | O23: ISLAM | P23: MALANG | Q23: 33553 | R23: =DATEDIF(Q23,$A$3,"Y") -> 29 | S23: =DATEDIF(Q23,$A$3,"YM") -> 1 | T23: S1 | U23: ADMINISTRASI BISNIS | V23: B | W23: K/1 | X23: WICAKSONO HARYO | Y23: 33482 | Z23: KAUTSARYO GHIFARYAN AL ABIDZAR | AA23: 42846 | AB23: =DATEDIF(AA23,$A$3,"Y") -> 3 | AC23: - | AD23: - | AE23: - | AI23: 3573015111910002 | AJ23: JL. DANAU JONGE H7 D-30 RT.04/RW.15 - MALANG | AK23: JL. DANAU JONGE H7 D-30 RT.04/RW.15 - MALANG | AN23: - | AO23: 081233625018 | AP23: SARIFA AINI | AQ23: 144-00-1746222-4 | AR23: MANDIRI | AS23: MALANG - KCP SUPRAPTO | AT23: -
A24: 13 | B24: 9919030015 | C24: SINTA ELMI RAHMAWATI | D24: ADMIN / REGISTRASI | E24: KONTRAK | F24: 43535 | G24: 43535 | J24: =DATEDIF(F24,$A$3,"Y") -> 1 | K24: =DATEDIF(F24,$A$3,"YM") -> 9 | N24: P | O24: ISLAM | P24: MALANG | Q24: 34251 | R24: =DATEDIF(Q24,$A$3,"Y") -> 27 | S24: =DATEDIF(Q24,$A$3,"YM") -> 2 | T24: S1 | U24: PSIKOLOGI | V24: O | W24: TK/0 | X24: - | Y24: - | Z24: - | AA24: - | AB24: - | AC24: - | AD24: - | AE24: - | AI24: 3579024910930001 | AJ24: JL. GAJAHMADA 3 NO 37 RT.03/RW.03 TULUNGREJO - BUMIAJI BATU | AK24: JL. GAJAHMADA 3 NO 37 RT.03/RW.03 TULUNGREJO - BUMIAJI BATU | AN24: - | AO24: 083848804994 | AP24: SINTA ELMI RAHMAWATI | AQ24: 144-00-1829106-9 | AR24: MANDIRI | AS24: MALANG - KCP SUPRAPTO | AT24: sinta.rahma90@gmail.com
A25: 14 | B25: 9919010010 | C25: KUSNUL YULIARIANTO | D25: SECURITY | E25: KONTRAK | F25: 43496 | G25: 43496 | J25: =DATEDIF(F25,$A$3,"Y") -> 1 | K25: =DATEDIF(F25,$A$3,"YM") -> 11 | N25: L | O25: ISLAM | P25: MALANG | Q25: 31595 | R25: =DATEDIF(Q25,$A$3,"Y") -> 34 | S25: =DATEDIF(Q25,$A$3,"YM") -> 6 | T25: SMK | U25: TEKNIK LISTRIK | V25: - | W25: K/2 | X25: NURKARMIA | Y25: - | Z25: NAFESA AZUKA | AA25: - | AB25: - | AC25: - | AD25: - | AE25: - | AI25: 3507210207860002 | AJ25: JL. PARANGARGO RT.09 RW.02 KEC WAGIR | AK25: JL. PARANGARGO RT.09 RW.02 KEC WAGIR | AN25: - | AO25: 083834658898 | AP25: KUSNUL YULIARIANTO | AQ25: 144-00-1818513-9 | AR25: MANDIRI | AS25: MALANG - KCP SUPRAPTO | AT25: gandulnoel@gmail.com
A26: 15 | B26: 9918070035 | C26: YULAIKA | D26: OFFICE GIRL / PANTRY | E26: KONTRAK | F26: 43299 | G26: 43299 | H26: 43664 | J26: =DATEDIF(F26,$A$3,"Y") -> 2 | K26: =DATEDIF(F26,$A$3,"YM") -> 5 | N26: P | O26: ISLAM | P26: MALANG | Q26: 25432 | R26: =DATEDIF(Q26,$A$3,"Y") -> 51 | S26: =DATEDIF(Q26,$A$3,"YM") -> 4 | T26: SD | U26: - | V26: - | W26: - | X26: - | Y26: - | Z26: - | AA26: - | AB26: - | AC26: - | AD26: - | AE26: - | AI26: 3507165708690002 | AJ26: JL. NAKULA 29 RT.03/RW.014 - TUMPANG | AN26: - | AO26: 082143604353 | AP26: YULAIKA | AQ26: 144-00-1763938-3 | AR26: MANDIRI | AS26: MALANG - KCP SUPRAPTO
A27: 16 | B27: 9918110040 | C27: ANNISYA FERONICA | D27: DESAIN GRAFIS | E27: KONTRAK | F27: 43407 | G27: 43407 | J27: =DATEDIF(F27,$A$3,"Y") -> 2 | K27: =DATEDIF(F27,$A$3,"YM") -> 2 | N27: P | O27: ISLAM | P27: BANYUWANGI | Q27: 34813 | R27: =DATEDIF(Q27,$A$3,"Y") -> 25 | S27: =DATEDIF(Q27,$A$3,"YM") -> 8 | T27: S-1 | U27: DESAIN PRODUCT | V27: O | W27: K/0 | X27: ICHSAN HANIF NUGROHO | Y27: 34823 | Z27: - | AA27: - | AB27: - | AC27: - | AD27: - | AE27: - | AI27: 3510166404950004 | AJ27: PERUM MENDUT REGENCY J/30, MOJOPANGGUNG - GIRI | AK27: JL. TELUK ETNA X KAV.145 NO.2 ARJOSARI - MALANG | AN27: - | AO27: 082257451869 | AP27: ANNISYA FERRONICA | AQ27: 144-00-1796729-7 | AR27: MANDIRI | AS27: MALANG - KCP SUPRAPTO | AT27: annisya.ferronica@gmail.com
A28: 17 | B28: 9919050019 | C28: MOH. ANDIKA RAISMA | D28: HRGA | E28: KONTRAK | F28: 43591 | G28: 43591 | J28: =DATEDIF(F28,$A$3,"Y") -> 1 | K28: =DATEDIF(F28,$A$3,"YM") -> 8 | N28: L | O28: ISLAM | P28: LAMONGAN | Q28: 35621 | R28: =DATEDIF(Q28,$A$3,"Y") -> 23 | S28: =DATEDIF(Q28,$A$3,"YM") -> 5 | T28: D1 | U28: KOMP. APLIKASI BISNIS ADM PERKANTORAN | V28: - | W28: TK/0 | X28: - | Y28: - | Z28: - | AA28: - | AB28: - | AC28: - | AD28: - | AE28: - | AI28: 3524021007970001 | AJ28: SONGO RT/RE 006/003 SONGOWARENG BLULUK LAMONGAN | AK28: JL CANDI BADUT KEC LOWOKWARU KOTA MALANG | AN28: - | AO28: 085707165618 | AP28: MOH. ANDIKA RAISMA | AQ28: 144-00-1846514-3 | AR28: MANDIRI | AS28: MALANG - KCP SUPRAPTO | AT28: raismaandika1@gmail.com
A29: 18 | B29: 9919100048 | C29: MARKUS VIRNANDA LUVI | D29: DESAIN GRAFIS | E29: KONTRAK | F29: 43741 | G29: 43741 | J29: =DATEDIF(F29,$A$3,"Y") -> 1 | K29: =DATEDIF(F29,$A$3,"YM") -> 3 | N29: L | O29: KRISTEN | P29: MALANG | Q29: 35150 | R29: =DATEDIF(Q29,$A$3,"Y") -> 24 | S29: =DATEDIF(Q29,$A$3,"YM") -> 9 | T29: D1 | U29: DESAIN GRAFIS | V29: O | W29: TK/0 | X29: - | Y29: - | Z29: - | AA29: - | AB29: - | AC29: - | AD29: - | AE29: - | AI29: 3507302603960001 | AJ29: DUSUN KRAJAN RT/RW 001/001 TAMAN KUNCARAN TIRTOYUDO MALANG | AK29: DUSUN KRAJAN RT/RW 001/001 TAMAN KUNCARAN TIRTOYUDO MALANG | AN29: - | AO29: 087859317997 | AP29: MARKUS VIRNANDA LUVI | AQ29: 144-00-1891228-4 | AR29: MANDIRI | AS29: MALANG - KCP SUPRAPTO
A30: 19 | B30: 9919100049 | C30: HENIP FATUL ULA | D30: ADM REVIEW | E30: KONTRAK | F30: 43750 | G30: 43750 | J30: =DATEDIF(F30,$A$3,"Y") -> 1 | K30: =DATEDIF(F30,$A$3,"YM") -> 2 | N30: P | O30: ISLAM | P30: MALANG | Q30: 36926 | R30: =DATEDIF(Q30,$A$3,"Y") -> 19 | S30: =DATEDIF(Q30,$A$3,"YM") -> 11 | T30: SMA | U30: AGRIBISNIS PERTANIAN | V30: O | W30: TK/0 | X30: - | Y30: - | Z30: - | AA30: - | AB30: - | AC30: - | AD30: - | AE30: - | AI30: 3507154402010003 | AJ30: JL MASJID KLAGEN TAJINAN RT 05 RW 03 TAJINAN MALANG | AK30: JL MASJID KLAGEN TAJINAN RT 05 RW 03 TAJINAN MALANG | AN30: - | AO30: 085850143301 | AP30: HENIP FATUL ULA | AQ30: 144-00-1891157-5 | AR30: MANDIRI | AS30: MALANG - KCP SUPRAPTO
A31: 20 | B31: 9919110050 | C31: SAMANTHA IGA PERMATASARI | D31: STAFF PAJAK | E31: KONTRAK | F31: 43770 | G31: 43770 | J31: =DATEDIF(F31,$A$3,"Y") -> 1 | K31: =DATEDIF(F31,$A$3,"YM") -> 2 | N31: P | O31: ISLAM | P31: MALANG | Q31: 35439 | R31: =DATEDIF(Q31,$A$3,"Y") -> 23 | S31: =DATEDIF(Q31,$A$3,"YM") -> 11 | T31: SMK | U31: AKUNTANSI | W31: TK/0 | AI31: 3507194901970002 | AJ31: JL. BARAKAN GG 5B RT02 RW04 GENENGAN PAKISAJI | AK31: JL. BARAKAN GG 5B RT02 RW04 GENENGAN PAKISAJI | AO31: 081230422528 | AP31: SAMANTHA IGA PERMATASARI | AQ31: 144-00-1902586-2 | AR31: MANDIRI | AS31: MALANG - KCP SUPRAPTO | AT31: samanthaiga8@gmail.com
A32: 21 | B32: 9919110052 | C32: ARUM SETIYONINGSIH | D32: LEGAL | E32: KONTRAK | F32: 43794 | G32: 43794 | J32: =DATEDIF(F32,$A$3,"Y") -> 1 | K32: =DATEDIF(F32,$A$3,"YM") -> 1 | N32: P | O32: ISLAM | P32: BOJONEGORO | Q32: 35755 | R32: =DATEDIF(Q32,$A$3,"Y") -> 23 | S32: =DATEDIF(Q32,$A$3,"YM") -> 1 | T32: S1 | U32: HUKUM | V32: A | W32: TK/0 | AI32: 3578286111970001 | AJ32: GENTING V/21/GENTING KALIANAK/ASEMROWO, BOJONEGORO | AK32: SAWOJAJAR IV | AO32: 081293751782 | AP32: ARUM SETIYONINGSIH | AQ32: 144-00-1902606-8 | AR32: MANDIRI | AS32: MALANG - KCP SUPRAPTO | AT32: arumstyn9@gmail.com
A33: 22 | B33: 9919110053 | C33: ANDYKA SYAHPUTRA | D33: ACCOUNTING | E33: KONTRAK | F33: 43795 | G33: 43795 | J33: =DATEDIF(F33,$A$3,"Y") -> 1 | K33: =DATEDIF(F33,$A$3,"YM") -> 1 | N33: L | O33: ISLAM | P33: MALANG | Q33: 34246 | R33: =DATEDIF(Q33,$A$3,"Y") -> 27 | S33: =DATEDIF(Q33,$A$3,"YM") -> 3 | T33: D2 | U33: ACCOUNTING | W33: TK/0 | AI33: 3573010410930002 | AJ33: JL. BATU AMARIL 38, RT/RW 02/04 PANDANWANGI, BLIMBING | AK33: JL. BATU AMARIL 38, RT/RW 02/04 PANDANWANGI, BLIMBING | AO33: 0895414552493 | AP33: ANDYKA SYAHPUTRA | AQ33: 144-00-1902619-1 | AR33: MANDIRI | AS33: MALANG - KCP SUPRAPTO | AT33: dykaputra1993@gmail.com
A34: 23 | B34: =NIK!$B$110 -> 9919120062 | C34: PIPIT CHOIRUL PUSPITASARI | D34: ADMIN MARKETING | E34: KONTRAK | F34: 43813 | G34: 43813 | J34: =DATEDIF(F34,$A$3,"Y") -> 1 | K34: =DATEDIF(F34,$A$3,"YM") -> 0 | N34: P | O34: ISLAM | P34: MALANG | Q34: 34875 | R34: =DATEDIF(Q34,$A$3,"Y") -> 25 | S34: =DATEDIF(Q34,$A$3,"YM") -> 6 | T34: S1 | U34: KESEJAHTERAAN SOSIAL | V34: B | W34: TK/0 | AI34: 3507186506950003 | AJ34: JL. KEDOYO TIMUR RT/RW 03/14, KEL. MANGLIAWAN KEC. PAKIS | AK34: JL. KEDOYO TIMUR RT/RW 03/14, KEL. MANGLIAWAN KEC. PAKIS | AO34: 081332450523 | AP34: PIPIT CHOIRUL PUSPITASARI | AQ34: 144-00-1859551-9 | AR34: MANDIRI | AS34: MALANG - KCP SUPRAPTO | AT34: pipitpita54@gmail.com
A35: 24 | B35: =NIK!$B$117 -> 9919120069 | C35: TRI NOVITA DANUATI | D35: ADMIN MARKETING | E35: KONTRAK | F35: 43820 | G35: 43820 | J35: =DATEDIF(F35,$A$3,"Y") -> 1 | K35: =DATEDIF(F35,$A$3,"YM") -> 0 | N35: P | O35: ISLAM | P35: LUMAJANG | Q35: 35391 | R35: =DATEDIF(Q35,$A$3,"Y") -> 24 | S35: =DATEDIF(Q35,$A$3,"YM") -> 1 | T35: S1 | U35: MANAJEMEN BISNIS INDUSTRI | V35: O | W35: TK/0 | AI35: 3508026211960001 | AJ35: SUMBERURIP RT/RW 03/02 PRONOJIWO, LUMAJANG | AK35: JL SUDIMORO NO 81 MOJOLANGU KEC LOWOKWARU | AO35: 085755339470 | AP35: TRI NOVITA DANUATI | AR35: MANDIRI | AS35: MALANG - KCP SUPRAPTO | AT35: trinovitadanuati@gmail.com
A36: 25 | B36: =NIK!$B$118 -> 9919120070 | C36: ONIS NABILLA NIRMALA SARI | D36: ADMIN MARKETING | E36: KONTRAK | F36: 43820 | G36: 43820 | J36: =DATEDIF(F36,$A$3,"Y") -> 1 | K36: =DATEDIF(F36,$A$3,"YM") -> 0 | N36: P | O36: ISLAM | P36: MALANG | Q36: 34871 | R36: =DATEDIF(Q36,$A$3,"Y") -> 25 | S36: =DATEDIF(Q36,$A$3,"YM") -> 6 | T36: S1 | U36: MANAJEMEN | V36: AB | W36: TK/0 | AI36: 3507056106950003 | AJ36: JL. WERKUDORO RT/RW 004/013 DAMPIT, MALANG | AK36: JL. WERKUDORO RT/RW 004/013 DAMPIT, MALANG | AO36: 081259483855 | AP36: ONIS NABILLA NIRMALA SARI | AR36: MANDIRI | AS36: MALANG - KCP SUPRAPTO | AT36: onisnabila@gmail.com
A37: 26 | B37: =NIK!$B$119 -> 9919120071 | C37: RIZKY NUR OKTAVIANI | D37: ADMIN MARKETING | E37: KONTRAK | F37: 43820 | G37: 43820 | J37: =DATEDIF(F37,$A$3,"Y") -> 1 | K37: =DATEDIF(F37,$A$3,"YM") -> 0 | N37: P | O37: ISLAM | P37: MALANG | Q37: 34614 | R37: =DATEDIF(Q37,$A$3,"Y") -> 26 | S37: =DATEDIF(Q37,$A$3,"YM") -> 2 | T37: S1 | U37: PENDIDIKAN BAHASA INGGRIS | W37: TK/0 | AI37: 3507184710940002 | AJ37: JL RAYA SEKARPURO 71 RT/RW 018/006 SEKARPURO, | AK37: JL RAYA SEKARPURO 71 RT/RW 018/006 SEKARPURO, | AO37: 082232495051 | AP37: RIZKY NUR OKTAVIANI | AR37: MANDIRI | AS37: MALANG - KCP SUPRAPTO | AT37: kikinur00@gmail.com
A38: 27 | B38: =NIK!$B$120 -> 9919120072 | C38: FARHAN AFIF MUADHOM | D38: ACCOUNTING | E38: KONTRAK | F38: 43823 | G38: 43823 | J38: =DATEDIF(F38,$A$3,"Y") -> 1 | K38: =DATEDIF(F38,$A$3,"YM") -> 0 | N38: L | O38: ISLAM | P38: MALANG | Q38: 35506 | R38: =DATEDIF(Q38,$A$3,"Y") -> 23 | S38: =DATEDIF(Q38,$A$3,"YM") -> 9 | T38: S1 | U38: AKUNTANSI | W38: TK/0 | AI38: 3572011703970002 | AJ38: JL. TIDAR NO 179 C RT 4 RW 4 KAUMAN KEPANJEN KIDUL BLITAR | AK38: JL CANDI BADUT 15 MOJOLANGU LOWOKWARU | AO38: 089680613107 | AP38: FARHAN AFIF MUADHOM | AR38: MANDIRI | AS38: MALANG - KCP SUPRAPTO | AT38: fourhanz.acc@gmail.com
A39: 28 | B39: =NIK!B121 -> 9919120073 | C39: RANGGA CHRISMA PUTRA | D39: GA | E39: KONTRAK | F39: 43823 | G39: 43823 | J39: =DATEDIF(F39,$A$3,"Y") -> 1 | K39: =DATEDIF(F39,$A$3,"YM") -> 0 | N39: L | O39: KRISTEN | P39: MALANG | Q39: 35059 | R39: =DATEDIF(Q39,$A$3,"Y") -> 25 | S39: =DATEDIF(Q39,$A$3,"YM") -> 0 | T39: S1 | U39: TEKNIK SIPIL DAN BANGUNAN | W39: TK/0 | AI39: 3573042612950004 | AJ39: JL. S.SUPRIADI VI/2964 RT 010 RW 006 SUKUN | AK39: JL. S.SUPRIADI VI/2964 RT 010 RW 006 SUKUN | AO39: 081336469038 | AP39: RANGGA CHRISMA PUTRA | AR39: MANDIRI | AS39: MALANG - KCP SUPRAPTO | AT39: ranggachrismaputra@gmsil.com
A40: 29 | B40: =NIK!B122 -> 9919120074 | C40: ZAINUL FANANI | D40: SECURITY | E40: KONTRAK | F40: 43823 | G40: 43823 | J40: =DATEDIF(F40,$A$3,"Y") -> 1 | K40: =DATEDIF(F40,$A$3,"YM") -> 0 | N40: L | O40: ISLAM | P40: MALANG | Q40: 27623 | R40: =DATEDIF(Q40,$A$3,"Y") -> 45 | S40: =DATEDIF(Q40,$A$3,"YM") -> 4 | T40: SMK | U40: MESIN OTOMOTIF | V40: B | W40: TK/0 | AI40: 3507221708750002 | AJ40: DSN SUMBERJO RT 006 RW 002 DAU, MALANG | AK40: DSN SUMBERJO RT 006 RW 002 DAU, MALANG | AO40: 08983480999 | AP40: ZAINUL FANANI | AR40: MANDIRI | AS40: MALANG - KCP SUPRAPTO
A41: 30 | B41: =NIK!B123 -> 9919120075 | C41: TOTOK MOEJIONO | D41: SECURITY | E41: KONTRAK | F41: 43823 | G41: 43823 | J41: =DATEDIF(F41,$A$3,"Y") -> 1 | K41: =DATEDIF(F41,$A$3,"YM") -> 0 | N41: L | O41: ISLAM | P41: MALANG | Q41: 27948 | R41: =DATEDIF(Q41,$A$3,"Y") -> 44 | S41: =DATEDIF(Q41,$A$3,"YM") -> 5 | T41: SMK | W41: TK/0 | AI41: 3573042707760001 | AJ41: GADANG 21C/24 RT 006 RW 004 GADANG SUKUN | AK41: GADANG 21C/24 RT 006 RW 004 GADANG SUKUN | AO41: 089688037798 | AP41: TOTOK MOEJIONO | AR41: MANDIRI | AS41: MALANG - KCP SUPRAPTO
A42: 31 | B42: =NIK!B124 -> 9919120076 | C42: YESI SILVIANA ENGGAR N | D42: CUSTOMER CARE | E42: KONTRAK | F42: 43824 | G42: 43824 | J42: =DATEDIF(F42,$A$3,"Y") -> 1 | K42: =DATEDIF(F42,$A$3,"YM") -> 0 | N42: P | O42: ISLAM | P42: MALANG | Q42: 34004 | R42: =DATEDIF(Q42,$A$3,"Y") -> 27 | S42: =DATEDIF(Q42,$A$3,"YM") -> 11 | T42: S1 | U42: PGSD | W42: TK/0 | AI42: 3521064402930001 | AJ42: BUDUG, RT/RW 013/005 KWADUNGAN, NGAWI | AK42: BUDUG, RT/RW 013/005 KWADUNGAN, NGAWI | AO42: 082228332766 | AP42: YESI SILVIANA ENGGAR N | AR42: MANDIRI | AS42: MALANG - KCP SUPRAPTO | AT42: YESISISILVIANA4@GMAIL.COM
...

Sheet 2020
B1: =+NOW() -> 44202.499
B2: DATA KARYAWAN MS GLOW OFFICE 2020
B3: No. | C3: N I K * | D3: NAMA LENGKAP | E3: POSISI | F3: STATUS KARYAWAN | G3: TANGGAL MULAI KERJA | H3: STATUS KEPEGAWAIAN | K3: MASA KERJA | O3: JENIS KELAMIN | P3: A G A M A | Q3: TEMPAT LAHIR | R3: Tanggal Lahir | S3: Umur | U3: PENDIDIKAN TERAKHIR | W3: GOLONGAN DARAH | X3: STATUS PERKAWINAN | Y3: ISTERI/SUAMI | AA3: ANAK I | AD3: ANAK II | AG3: ANAK III | AJ3: KTP * | AL3: ALAMAT TINGGAL | AM3: NO. BPJS KETENAGAKERJAAN | AN3: NO. BPJS KESEHATAN | AO3: NPWP | AP3: NO. HP | AQ3: ACCOUNT BANK * | AU3: EMAIL
K4: =+NOW() -> 44202.499 | M4: MULAI | N4: AKHIR | U4: Pendidikan | V4: Jurusan | Y4: Nama | Z4: Tgl Lahir | AA4: Nama | AB4: Tgl Lahir | AC4: Umur | AD4: Nama | AE4: Tgl Lahir | AF4: Umur | AG4: Nama | AH4: Tgl Lahir | AI4: Umur | AJ4: NOMOR KTP | AK4: ALAMAT KTP | AQ4: Atas Nama (sesuai dibuku rekening) | AR4: NOMOR REKENING | AS4: BANK | AT4: CABANG
H5: KONTRAK 1 (PKWT-1) | I5: KONTRAK 2 (PKWT-2) | J5: TETAP | K5: Tahun | L5: Bulan | R5: =+NOW() -> 44202.499 | S5: Tahun | T5: Bulan
B6: MANAGEMENT
B7: 1 | C7: OWNER | D7: SHANDY PURNAMASARI | E7: KOMISARIS | O7: P | P7: ISLAM | Q7: SURABAYA | R7: 33521 | S7: =DATEDIF(R7,$B$1,"Y") -> 29 | T7: =DATEDIF(R7,$B$1,"YM") -> 2 | X7: K/1 | Y7: GILANG WIDYA PRAMANA | Z7: 32632 | AA7: FELICIA LASHA ZAFEERA | AB7: 41559 | AC7: =DATEDIF(AB7,$B$1,"Y") -> 7 | AL7: GREENWOOD GOLF INDAH NO. 5 - MALANG
B8: 2 | D8: GILANG WIDYA PRAMANA | E8: DIREKTUR | O8: L | P8: ISLAM | Q8: PROBOLINGGO | R8: 32632 | S8: =DATEDIF(R8,$B$1,"Y") -> 31 | T8: =DATEDIF(R8,$B$1,"YM") -> 8 | X8: K/1 | Y8: SHANDY PURNAMASARI | Z8: 33521 | AA8: FELICIA LASHA ZAFEERA | AB8: 41559 | AC8: =DATEDIF(AB8,$B$1,"Y") -> 7 | AJ8: 3574040405890001 | AK8: JL. KH AHMAD DAHLAN 123 RT.01/RW.01 PROBOLINGGO | AL8: GREENWOOD GOLF INDAH NO. 5 - MALANG | AO8: 35.447.918.0.625.000 | AP8: 081233732340
B9: MANAGER
A10: 1 | B10: 1 | C10: 9920100146 | D10: SHEILA MARTHALIA | E10: GENERAL MANAGER | F10: KONTRAK | G10: 44105 | H10: 44105 | K10: =DATEDIF(G10,$B$1,"Y") -> 0 | L10: =DATEDIF(G10,$B$1,"YM") -> 3 | O10: P | P10: ISLAM | Q10: MALANG | R10: 33246 | S10: =DATEDIF(R10,$B$1,"Y") -> 29 | T10: =DATEDIF(R10,$B$1,"YM") -> 11 | U10: S-1 | V10: EKONOMI PEMBANGUNAN | W10: O | X10: TK/0 | AJ10: 3572024801910001 | AK10: JL RANDU AGUNG NO 53 002/001 KARANGSARI SUKOREJO | AL10: JL RANDU AGUNG NO 53 002/001 KARANGSARI SUKOREJO | AO10: 66.640.955.2-609.000 | AP10: 081335118857 | AQ10: SHEILA MARTHALIA | AR10: 144-00-1763260-2 | AS10: MANDIRI | AT10: MALANG - KCP SUPRAPTO | AU10: pangkey.sheila@gmail.com
A11: 2 | B11: 2 | C11: 9918080037 | D11: RIDA' MILLATI | E11: MANAGER MARKETING | F11: KONTRAK | G11: 43340 | H11: 43340 | I11: 43705 | K11: =DATEDIF(G11,$B$1,"Y") -> 2 | L11: =DATEDIF(G11,$B$1,"YM") -> 4 | O11: P | P11: ISLAM | Q11: MALANG | R11: 34553 | S11: =DATEDIF(R11,$B$1,"Y") -> 26 | T11: =DATEDIF(R11,$B$1,"YM") -> 4 | U11: S-1 | V11: DESAIN PRODUCT | W11: - | X11: TK/1 | Y11: - | Z11: - | AA11: MIKAYLA ALESHA VALERIE | AB11: 42598 | AC11: =DATEDIF(AB11,$B$1,"Y") -> 4 | AD11: - | AE11: - | AF11: - | AJ11: 3573044708940000 | AK11: JL. SIMPANG LOWOKDORO I no. 5 RT.10/RW.04 KEC. SUKUN - MALANG | AL11: JL. SIMPANG LOWOKDORO I no. 5 RT.10/RW.04 KEC. SUKUN - MALANG | AO11: 85.695.573.7-623.000 | AP11: 085257396000 | AQ11: RIDA' MILLATI | AR11: 144-00-1771808-8 | AS11: MANDIRI | AT11: MALANG - KCP SUPRAPTO | AU11: rida.millati29@gmail.com | AV11: BPJS TK
A12: 3 | B12: 3 | C12: 9918040002 | D12: CHANDRA MAHARDHIKA | E12: MANAGER PRODUCT | F12: KONTRAK | G12: 43202 | H12: 43202 | I12: 43567 | K12: =DATEDIF(G12,$B$1,"Y") -> 2 | L12: =DATEDIF(G12,$B$1,"YM") -> 8 | O12: L | P12: ISLAM | Q12: MALANG | R12: 32362 | S12: =DATEDIF(R12,$B$1,"Y") -> 32 | T12: =DATEDIF(R12,$B$1,"YM") -> 4 | U12: S-1 | V12: MANAJ. SUMBER DAYA MANUSIA | W12: O | X12: K/1 | Y12: FEBRIANA PUTRI ASIH VALENTINE | Z12: 32188 | AA12: ALARIC GHIBRAN MAHARDHIKA | AB12: 42531 | AC12: =DATEDIF(AB12,$B$1,"Y") -> 4 | AD12: - | AE12: - | AF12: - | AJ12: 3573040708880003 | AK12: JL. RANAKAH Q-9 TIDAR - MALANG | AL12: JL. SIMPANG LOWOKDORO NO. 2 KAV. 1 - MALANG | AO12: 97.290.407.2.623.000 | AP12: 081233993341 | AQ12: CHANDRA MAHARDHIKA | AR12: 144-00-1739415-3 | AS12: MANDIRI | AT12: MALANG - KCP SUPRAPTO | AU12: mahardhika.chandra7888@gmail.com | AV12: BPJS TK
A13: 4 | B13: 4 | C13: 9919020011 | D13: VENNA ROSIA MARHETA | E13: MANAGER HRGA | F13: KONTRAK | G13: 43497 | H13: 43497 | I13: 43862 | K13: =DATEDIF(G13,$B$1,"Y") -> 1 | L13: =DATEDIF(G13,$B$1,"YM") -> 11 | O13: P | P13: ISLAM | Q13: MALANG | R13: 31666 | S13: =DATEDIF(R13,$B$1,"Y") -> 34 | T13: =DATEDIF(R13,$B$1,"YM") -> 3 | U13: S-2 | V13: MANAJ. SUMBER DAYA MANUSIA | W13: A | X13: K/1 | Y13: MOH. HASIM AS'ARI | Z13: 30600 | AA13: GHAIDA AMETHYSA SHANUM | AB13: 41939 | AC13: =DATEDIF(AB13,$B$1,"Y") -> 6 | AD13: - | AE13: - | AF13: - | AJ13: 3573045109860002 | AK13: JL. RAYA GADANG XB NO 49 RT.04/RW.05 KEL. GADANG - MALANG | AL13: JL. RAYA GADANG XB NO 48 RT.04/RW.05 KEL. GADANG - MALANG | AO13: 08.735.462.7-623.000 | AP13: 0895627070220 | AQ13: VENNA ROSIA MARHETA | AR13: 144-00-1818033-8 | AS13: MANDIRI | AT13: MALANG - KCP SUPRAPTO | AU13: verota.pussie@gmail.com | AV13: BPJS TK
A14: 5 | B14: 5 | C14: 9919110053 | D14: ANDYKA SYAHPUTRA | E14: MANAGER ACCOUNTING | F14: KONTRAK | G14: 43795 | H14: 43795 | K14: =DATEDIF(G14,$B$1,"Y") -> 1 | L14: =DATEDIF(G14,$B$1,"YM") -> 1 | O14: L | P14: ISLAM | Q14: MALANG | R14: 34246 | S14: =DATEDIF(R14,$B$1,"Y") -> 27 | T14: =DATEDIF(R14,$B$1,"YM") -> 3 | U14: D2 | V14: ACCOUNTING | W14: A | X14: TK/0 | AJ14: 3573010410930002 | AK14: JL. BATU AMARIL 38, RT/RW 02/04 PANDANWANGI, BLIMBING | AL14: JL. BATU AMARIL 38, RT/RW 02/04 PANDANWANGI, BLIMBING | AP14: 0895414552493 | AQ14: ANDYKA SYAHPUTRA | AR14: 144-00-1902619-1 | AS14: MANDIRI | AT14: MALANG - KCP SUPRAPTO | AU14: dykaputra1993@gmail.com
A15: 6 | B15: 6 | C15: 9920100145 | D15: FATWA IHYA' AZIZA | E15: MANAGER PENJUALAN | F15: KONTRAK | G15: 44105 | H15: 44105 | K15: =DATEDIF(G15,$B$1,"Y") -> 0 | L15: =DATEDIF(G15,$B$1,"YM") -> 3 | O15: P | P15: ISLAM | Q15: SURABAYA | R15: 33624 | S15: =DATEDIF(R15,$B$1,"Y") -> 28 | T15: =DATEDIF(R15,$B$1,"YM") -> 11 | U15: S1 | V15: EKONOMI PEMBANGUNAN | X15: TK/0 | AJ15: 3578266101920002 | AK15: JL. SUTOREJO SELATAN 7 NO 6, 005/008 MULYOREJO, SURABAYA | AL15: JL. SUTOREJO SELATAN 7 NO 6, 005/008 MULYOREJO, SURABAYA | AQ15: FATWA IHYA' AZIZA | AR15: 144-00-1980484-5 | AS15: MANDIRI | AT15: MALANG - KCP SUPRAPTO
A16: 7 | B16: 7 | C16: 9920110154 | D16: MIRZA HENDRAWAN | E16: MANAGER DEVELOPMENT | F16: KONTRAK | G16: 44136 | H16: 44136 | K16: =DATEDIF(G16,$B$1,"Y") -> 0 | L16: =DATEDIF(G16,$B$1,"YM") -> 2 | O16: L | P16: ISLAM | Q16: MALANG | R16: 31740 | S16: =DATEDIF(R16,$B$1,"Y") -> 34 | T16: =DATEDIF(R16,$B$1,"YM") -> 1 | U16: S1 | X16: TK/0 | Y16: DYAN PERMATA SARI | Z16: 31949 | AA16: RENAYLA NOURRIVIRDEEZ | AB16: 39454 | AC16: =DATEDIF(AB16,$B$1,"Y") -> 12 | AD16: RAYHAN ZAFA HENDRAWAN | AE16: 42652 | AF16: =DATEDIF(AE16,$B$1,"Y") -> 4 | AG16: RAKHA FAZA HENDRAWAN | AH16: 42652 | AI16: =DATEDIF(AH16,$B$1,"Y") -> 4 | AJ16: 3573052411860005 | AK16: JL. SIMPANG CANDI TROWULAN 5 002/003 MOJOLANGU LOWOKWARU | AL16: JL. SIMPANG CANDI TROWULAN 5 002/003 MOJOLANGU LOWOKWARU | AO16: 35.029.327.0-652.000 | AQ16: MIRZA HENDRAWAN | AR16: 152-00-1183402-1 | AS16: MANDIRI
B18: BISNIS DEVELOPMENT
A19: 8 | B19: 1 | C19: 992030105 | D19: RIKO TRIE SAPUTRA | E19: SPV MS GLOW MEN | F19: KONTRAK | G19: 43904 | H19: 43904 | K19: =DATEDIF(G19,$B$1,"Y") -> 0 | L19: =DATEDIF(G19,$B$1,"YM") -> 9 | O19: L | P19: ISLAM | Q19: BANGKALAN | R19: 34294 | S19: =DATEDIF(R19,$B$1,"Y") -> 27 | T19: =DATEDIF(R19,$B$1,"YM") -> 1 | U19: S1 | V19: TI - DG | W19: A+ | X19: TK/0 | Y19: GREXITA VETA SANDIKA | Z19: 36136 | AA19: GRITHA ALEONA VALERIE | AB19: 43210 | AJ19: 3526012111930003 | AK19: JL. JOKOTOLE III RT 04/RW 04 BANGKALAN | AL19: JL. IKAN GURAMI 24 MALANG | AO19: 92.498.503.9-652.000 | AP19: 087859500686 | AQ19: RIKO TRIE SAPUTRA | AR19: 144-00-1712394-1 | AS19: MANDIRI | AT19: MALANG - KCP SUPRAPTO | AU19: rikosaputra337@gmail.com
A20: 9 | B20: 2 | C20: 9918090038 | D20: ANIKE WULANDARI | E20: ADMIN / MARKETING | F20: KONTRAK | G20: 43362 | H20: 43362 | I20: 43574 | K20: =DATEDIF(G20,$B$1,"Y") -> 2 | L20: =DATEDIF(G20,$B$1,"YM") -> 3 | O20: P | P20: ISLAM | Q20: MALANG | R20: 34925 | S20: =DATEDIF(R20,$B$1,"Y") -> 25 | T20: =DATEDIF(R20,$B$1,"YM") -> 4 | U20: S1 | V20: KESEHATAN MASYARAKAT | W20: - | X20: TK/0 | Y20: - | Z20: - | AA20: - | AB20: - | AC20: - | AD20: - | AE20: - | AJ20: 3507185408950003 | AK20: SINDUREJO RT.4/RW.3 BANJAREJO PAKIS - KAB. MALANG | AL20: SINDUREJO RT.4/RW.3 BANJAREJO PAKIS - KAB. MALANG | AO20: - | AP20: 085646660730 | AQ20: ANIKE WULANDARI | AR20: 144-00-1778916-2 | AS20: MANDIRI | AT20: MALANG - KCP SUPRAPTO | AU20: anikewulandarii@gmail.com | AV20: BPJS TK
A21: 10 | B21: 3 | C21: 992030104 | D21: RENDY ARDIAN PRATAMA | E21: DESAIN GRAFIS | F21: KONTRAK | G21: 43904 | H21: 43904 | K21: =DATEDIF(G21,$B$1,"Y") -> 0 | L21: =DATEDIF(G21,$B$1,"YM") -> 9 | O21: L | P21: KRISTEN | Q21: MALANG | R21: 35650 | S21: =DATEDIF(R21,$B$1,"Y") -> 23 | T21: =DATEDIF(R21,$B$1,"YM") -> 4 | U21: S1 | V21: DESAIN GRAFIS | X21: TK/0 | AJ21: 3507210808970003 | AK21: JL. RAYA GONDOWANGI NO 46, WAGIR KAB. MALANG | AL21: JL. RAYA GONDOWANGI NO 46, WAGIR KAB. MALANG | AP21: 085234811314 | AQ21: RENDY ARDIAN PRATAMA | AR21: 144-00-1938310-5 | AS21: MANDIRI | AT21: MALANG - KCP SUPRAPTO | AV21: BPJS TK
A22: 11 | B22: 4 | C22: 9919120055 | D22: WICAKSONO HARYO PRAKOSO | E22: ADMIN PENJUALAN | F22: KONTRAK | G22: 43801 | H22: 43801 | K22: =DATEDIF(G22,$B$1,"Y") -> 1 | L22: =DATEDIF(G22,$B$1,"YM") -> 1 | O22: L | P22: ISLAM | Q22: SIDOARJO | R22: 33482 | S22: =DATEDIF(R22,$B$1,"Y") -> 29 | T22: =DATEDIF(R22,$B$1,"YM") -> 4 | U22: D-III | V22: TEKNIK ELEKTRO | W22: O | X22: TK/0 | Y22: SARIFA AINI | AA22: KAUTSARYO GHIFARYAN AL ABIDZAR | AB22: 42846 | AC22: =DATEDIF(AB22,$B$1,"Y") -> 3 | AJ22: 3573030109910001 | AK22: JL. DANAU RAWA PENING II /H5 D1, RT/RW 03/14, MADYOPURO | AL22: JL. DANAU RAWA PENING II /H5 D1, RT/RW 03/14, MADYOPURO | AP22: 081233625018 | AQ22: WICAKSONO HARYO PRAKOSO | AR22: 144-00-1908240-0 | AS22: MANDIRI | AT22: MALANG - KCP SUPRAPTO | AV22: BPJS TK
A23: 12 | B23: 5 | C23: 9919120060 | D23: SAIFUR ROUUF | E23: DESIGN | F23: KONTRAK | G23: 43811 | H23: 43811 | K23: =DATEDIF(G23,$B$1,"Y") -> 1 | L23: =DATEDIF(G23,$B$1,"YM") -> 0 | O23: L | P23: ISLAM | Q23: JEPARA | R23: 34239 | S23: =DATEDIF(R23,$B$1,"Y") -> 27 | T23: =DATEDIF(R23,$B$1,"YM") -> 3 | U23: D-II | V23: INFORMATIC COMPUTER | W23: O | X23: TK/0 | AJ23: 3320062709930003 | AK23: JL. KARTINI 57 KAUMAN RT/RW KAUMAN, JEPARA | AL23: JL. KARTINI 57 KAUMAN RT/RW KAUMAN, JEPARA | AP23: 082232929651 | AQ23: SAIFUR ROUUF | AR23: 144-00-1908248-3 | AS23: MANDIRI | AT23: MALANG - KCP SUPRAPTO | AV23: BPJS TK
A24: 13 | B24: 6 | C24: 9919120056 | D24: RATNA KURNIAWATI | E24: ADMIN PENJUALAN | F24: KONTRAK | G24: 43801 | H24: 43801 | K24: =DATEDIF(G24,$B$1,"Y") -> 1 | L24: =DATEDIF(G24,$B$1,"YM") -> 1 | O24: P | P24: ISLAM | Q24: MALANG | R24: 33979 | S24: =DATEDIF(R24,$B$1,"Y") -> 27 | T24: =DATEDIF(R24,$B$1,"YM") -> 11 | U24: S-1 | V24: EKONOMI PEMBANGUNAN | W24: B | X24: TK/0 | AJ24: 3573035001930006 | AK24: JL. BANDARA TIMIKA BLOK CK – 19, RT/RW 04/09, CEMOROKANDANG, KEDUNGKANDANG | AL24: JL. BANDARA TIMIKA BLOK CK – 19, RT/RW 04/09, CEMOROKANDANG, KEDUNGKANDANG | AP24: 082331568118 | AQ24: RATNA KURNIAWATI | AR24: 144-00-1908235-0 | AS24: MANDIRI | AT24: MALANG - KCP SUPRAPTO | AV24: BPJS TK
A25: 14 | B25: 7 | C25: 992060119 | D25: LODY SAMPURNA | E25: MARKOM | F25: KONTRAK | G25: 43991 | H25: 43991 | K25: =DATEDIF(G25,$B$1,"Y") -> 0 | L25: =DATEDIF(G25,$B$1,"YM") -> 6 | O25: P | P25: ISLAM | Q25: MALANG | R25: 35667 | S25: =DATEDIF(R25,$B$1,"Y") -> 23 | T25: =DATEDIF(R25,$B$1,"YM") -> 4 | U25: S1 | V25: TIDG | W25: A RH+ | X25: TK/0 | AJ25: 3579022508970008 | AK25: JL. TANJUNG 59 BULUKERTO 001/004 BULUKERTO, BUMIAJI MALANG | AL25: JL. TANJUNG 59 BULUKERTO 001/004 BULUKERTO, BUMIAJI MALANG | AP25: 082141427637 | AQ25: LODY SAMPURNA | AR25: 144-00-1948984-5 | AS25: MANDIRI | AT25: MALANG - KCP SUPRAPTO | AU25: isampurna71@gmail.com
A26: 15 | B26: 8 | C26: 9920120163 | D26: ARISMA LULI DIANA | E26: ADMIN PENJUALAN (vape) | F26: KONTRAK | G26: 44186 | H26: 44186 | K26: =DATEDIF(G26,$B$1,"Y") -> 0 | L26: =DATEDIF(G26,$B$1,"YM") -> 0 | O26: P | P26: ISLAM | Q26: GRESIK | R26: 35177 | S26: =DATEDIF(R26,$B$1,"Y") -> 24 | T26: =DATEDIF(R26,$B$1,"YM") -> 8 | U26: S1 | V26: ILMU KOMUNIKASI | W26: O | X26: TK/0 | AJ26: 3525036204960001 | AK26: LINGKUNGAN NENGGALAH RT/RW 006/002 DALEGAN KEC PANCENG GRESIK | AL26: JL CANDI 2 GANG BAKUNG INDAH NO 135 KARANGBESUKI SUKUN MALANG | AP26: 085646475519 | AQ26: ARISMA LULI DIANA | AR26: 178-00-0331248-1 | AS26: MANDIRI | AT26: GRESIK | AU26: arisma.lulidiana@gamil.com
A27: 16 | B27: 9 | C27: 9920120164 | D27: RYAN ANDRIA NUGROHO | E27: GRAPHIC DESIGN (vape) | F27: KONTRAK | G27: 44186 | H27: 44186 | K27: =DATEDIF(G27,$B$1,"Y") -> 0 | L27: =DATEDIF(G27,$B$1,"YM") -> 0 | O27: L | P27: ISLAM | Q27: PATI | R27: 35836 | S27: =DATEDIF(R27,$B$1,"Y") -> 22 | T27: =DATEDIF(R27,$B$1,"YM") -> 10 | U27: S1 | V27: INFORMATIKA | W27: - | X27: TK/0 | AJ27: 3318051002980003 | AK27: JETAK RT/RW 003/001 PUCAKWANGI PATI JAWA TENGAH | AL27: GG XI NO 85B RT/RW 005/002 SAWOJAJAR KEDUNGKANDANG MALANG | AP27: 081393103838 | AQ27: RYAN ANDRIA NUGROHO | AR27: 184-00-0232835-7 | AS27: MANDIRI | AT27: PATI | AU27: nugrohoandria@gmail.com
A28: 17 | B28: 10 | C28: 9920110159 | D28: AGAM SUNANTO | E28: DESIGN | F28: KONTRAK | G28: 44151 | H28: 44151 | K28: =DATEDIF(G28,$B$1,"Y") -> 0 | L28: =DATEDIF(G28,$B$1,"YM") -> 1 | O28: L | P28: ISLAM | Q28: MALANG | R28: 34862 | S28: =DATEDIF(R28,$B$1,"Y") -> 25 | T28: =DATEDIF(R28,$B$1,"YM") -> 6 | U28: S1 | V28: DESIGN PRODUCT | X28: K/0 | AJ28: 3507311206950001 | AK28: DSN KRAJAN 003/001 JAMBUWER KROMENGAN MALANG | AL28: DSN KRAJAN 003/001 JAMBUWER KROMENGAN MALANG | AP28: 082131931669 | AQ28: AGAM SUNANTO | AR28: 144-00-1980149-4 | AS28: MANDIRI | AT28: MALANG - KCP SUPRAPTO | AU28: agam.sunanto@gmail.com
A29: 18 | B29: 11 | C29: 992110170 | D29: AVILLA FLORENCIA GITAVIONNI | E29: ADM SOSMED (men) | F29: KONTRAK | G29: 44202 | H29: 44202 | K29: =DATEDIF(G29,$B$1,"Y") -> 0 | L29: =DATEDIF(G29,$B$1,"YM") -> 0 | O29: P | P29: KRISTEN | Q29: TULUNGAGUNG | R29: 35342 | S29: =DATEDIF(R29,$B$1,"Y") -> 24 | T29: =DATEDIF(R29,$B$1,"YM") -> 3 | U29: S1 | V29: SASTRA INGGRIS | W29: A | X29: K/0 | AJ29: 3504114410960004 | AK29: PULOSARI, RT/RW 002/009 PULOSARI, NGUNUT KAB TULUNGAGUNG | AL29: JL BENDUNGAN SEMPUR NO 27 SUMBERSARI MALANG | AP29: 081330858957 | AQ29: AVILLA FLORENCIA GITAVIONNI | AS29: MANDIRI | AT29: MALANG - KCP SUPRAPTO | AU29: vvionna12@gmail.com
B31: PENJUALAN
A32: 19 | B32: 1 | C32: 9918050033 | D32: SARIFA AINI | E32: MARKETING | F32: KONTRAK | G32: 43222 | H32: 43222 | I32: 43587 | K32: =DATEDIF(G32,$B$1,"Y") -> 2 | L32: =DATEDIF(G32,$B$1,"YM") -> 8 | O32: P | P32: ISLAM | Q32: MALANG | R32: 33553 | S32: =DATEDIF(R32,$B$1,"Y") -> 29 | T32: =DATEDIF(R32,$B$1,"YM") -> 1 | U32: S1 | V32: ADMINISTRASI BISNIS | W32: B | X32: K/1 | Y32: WICAKSONO HARYO | Z32: 33482 | AA32: KAUTSARYO GHIFARYAN AL ABIDZAR | AB32: 42846 | AC32: =DATEDIF(AB32,$B$1,"Y") -> 3 | AD32: - | AE32: - | AF32: - | AJ32: 3573015111910002 | AK32: JL. DANAU JONGE H7 D-30 RT.04/RW.15 - MALANG | AL32: JL. DANAU JONGE H7 D-30 RT.04/RW.15 - MALANG | AO32: - | AP32: 081233625018 | AQ32: SARIFA AINI | AR32: 144-00-1746222-4 | AS32: MANDIRI | AT32: MALANG - KCP SUPRAPTO | AU32: - | AV32: BPJS TK
